this can not catch where the execption is thrown
using assertThatThrownBy instead